Workbook
Name _xlchart.v1.6: 'Profit Insights'!$B$2:$B$204
Name _xlchart.v1.3: 'Profit Insights'!$K$10
Name _xlchart.v1.4: 'Profit Insights'!$K$10:$L$10
Name _xlchart.v1.1: 'Profit Insights'!$B$2:$B$204
Name _xlchart.v1.2: 'Profit Insights'!$G$10
Name _xlchart.v1.0: 'Profit Insights'!$B$1
Name _xlchart.v1.5: 'Profit Insights'!$B$1

Sheet My trades
A1: Trade | B1: Stock exchange | C1: Region | D1: Date added | E1: Quantity | F1: Buy Price | G1: Date sold | H1: Sell Price
A2: agfgcfxt | B2: Bombay Stock Exchange | C2: India | D2: 44841 | E2: 7 | F2: 0.28318547 | G2: 45092 | H2: 0.55712981
A3: aieoltom | B3: Tehran Stock Exchange | C3: Iran | D3: 44200 | E3: 2 | F3: 0.64142747 | G3: 45039 | H3: 0.88983598
A4: almuieaq | B4: National Stock Exchange | C4: India | D4: 44519 | E4: 6 | F4: 0.98092818 | G4: 44968 | H4: 0.72256313
A5: apxkynfx | B5: SIX Swiss Exchange | C5: Switzerland | D5: 44664 | E5: 1 | F5: 0.4602753 | G5: 44971 | H5: 0.8279317
A6: bbjeprsq | B6: Bombay Stock Exchange | C6: India | D6: 44351 | E6: 9 | F6: 0.55179845 | G6: 44977 | H6: 0.19789786
A7: bcizkhng | B7: Euronext | C7: Europe | D7: 44529 | E7: 1 | F7: 0.30386849 | G7: 44969 | H7: 0.97814413
A8: bdkloegq | B8: Korea Exchange | C8: South Korea | D8: 44500 | E8: 3 | F8: 0.10094556 | G8: 44930 | H8: 0.40740538
A9: beszhcyh | B9: Johannesburg Stock Exchange | C9: South Africa | D9: 44584 | E9: 4 | F9: 0.1365207 | G9: 44991 | H9: 0.38969057
A10: bjfxoyxb | B10: Toronto Stock Exchange | C10: Canada | D10: 44472 | E10: 10 | F10: 0.41670439 | G10: 45045 | H10: 0.54934508
A11: bpjmrhjo | B11: Euronext | C11: Europe | D11: 44587 | E11: 6 | F11: 0.24316987 | G11: 44987 | H11: 0.42023282
A12: brxwzrct | B12: Deutsche Börse AG | C12: Germany | D12: 44407 | E12: 5 | F12: 0.80079383 | G12: 44996 | H12: 0.8966623
A13: bumcnvke | B13: Bombay Stock Exchange | C13: India | D13: 44543 | E13: 10 | F13: 0.63898127 | G13: 45031 | H13: 0.77496722
... A201: zvxjotpr | B201: B3 Brasil Bolsa Balcão | C201: Brazil | D201: 44502 | E201: 8 | F201: 0.91352809 | G201: 44978 | H201: 0.13798579
D203: ​

Sheet Stock Exchanges
A1: Region | B1: Quantity
A2: India | B2: 7
A3: Iran | B3: 2 | F3: Tassazione necessaria
A4: India | B4: 6 | F4: =IF(E4>67, "SI", "NO") -> SI
A5: Switzerland | B5: 1 | F5: =IF(E5>67, "SI", "NO") -> SI
A6: India | B6: 9 | F6: =IF(E6>67, "SI", "NO") -> NO
A7: Europe | B7: 1 | F7: =IF(E7>67, "SI", "NO") -> SI
A8: South Korea | B8: 3 | F8: =IF(E8>67, "SI", "NO") -> SI
A9: South Africa | B9: 4 | F9: =IF(E9>67, "SI", "NO") -> SI
A10: Canada | B10: 10 | F10: =IF(E10>67, "SI", "NO") -> NO
A11: Europe | B11: 6 | F11: =IF(E11>67, "SI", "NO") -> SI
A12: Germany | B12: 5 | F12: =IF(E12>67, "SI", "NO") -> NO
A13: India | B13: 10 | F13: =IF(E13>67, "SI", "NO") -> NO
A14: India | B14: 8 | F14: =IF(E14>67, "SI", "NO") -> NO
A15: Saudi Arabia | B15: 6 | F15: =IF(E15>67, "SI", "NO") -> NO
... A20: India | B20: 1 | F20: =IF(E20>67, "SI", "NO") -> SI
A21: Japan | B21: 1
A22: United Kingdom | B22: 1
A23: India | B23: 9
A24: Brazil | B24: 2
A25: United States | B25: 3
A26: Canada | B26: 2
A27: Brazil | B27: 8
A28: South Korea | B28: 7
A29: India | B29: 1
A30: India | B30: 3
A31: Germany | B31: 1
A32: United Kingdom | B32: 7
... A201: Brazil | B201: 8

Sheet Profit Insights
A1: Trade | B1: Holding Period (Days) | C1: Profit
A2: hpvfzslv | B2: ='My trades'!G60-'My trades'!D60 -> 30 | C2: =('My trades'!H60-'My trades'!F60)*'My trades'!E60 -> 1.1391515
A3: oplgqwal | B3: ='My trades'!G113-'My trades'!D113 -> 42 | C3: =('My trades'!H113-'My trades'!F113)*'My trades'!E113 -> -6.419612
A4: dpaxyvrx | B4: ='My trades'!G26-'My trades'!D26 -> 51 | C4: =('My trades'!H26-'My trades'!F26)*'My trades'!E26 -> -0.32528107
A5: mxmztjnk | B5: ='My trades'!G101-'My trades'!D101 -> 57 | C5: =('My trades'!H101-'My trades'!F101)*'My trades'!E101 -> 1.1022958
A6: pyljmfku | B6: ='My trades'!G123-'My trades'!D123 -> 58 | C6: =('My trades'!H123-'My trades'!F123)*'My trades'!E123 -> -3.7137818
A7: nheepbxg | B7: ='My trades'!G103-'My trades'!D103 -> 69 | C7: =('My trades'!H103-'My trades'!F103)*'My trades'!E103 -> -2.6947242
A8: fucpzbpk | B8: ='My trades'!G41-'My trades'!D41 -> 71 | C8: =('My trades'!H41-'My trades'!F41)*'My trades'!E41 -> -1.6706743
A9: ciykrilb | B9: ='My trades'!G17-'My trades'!D17 -> 78 | C9: =('My trades'!H17-'My trades'!F17)*'My trades'!E17 -> -4.0381768 | G9: Media | H9: Moda | I9: Mediana | J9: Dev. St. | K9: Min | L9: Max
A10: yjrqvwdc | B10: ='My trades'!G187-'My trades'!D187 -> 80 | C10: =('My trades'!H187-'My trades'!F187)*'My trades'!E187 -> -0.13532525 | G10: =AVERAGE(B:B) -> 449.795 | H10: =MODE(B:B) -> 623 | I10: =MEDIAN(B:B) -> 444 | J10: =_xlfn.STDEV.P(B2:B201) -> 222.2356 | K10: =MIN(B2:B201) -> 30 | L10: =MAX(B2:B201) -> 862
A11: twxakkhn | B11: ='My trades'!G152-'My trades'!D152 -> 87 | C11: =('My trades'!H152-'My trades'!F152)*'My trades'!E152 -> 2.332716
A12: jarhgmub | B12: ='My trades'!G70-'My trades'!D70 -> 88 | C12: =('My trades'!H70-'My trades'!F70)*'My trades'!E70 -> 0.43584937
A13: gcndrwci | B13: ='My trades'!G43-'My trades'!D43 -> 106 | C13: =('My trades'!H43-'My trades'!F43)*'My trades'!E43 -> 1.7198007 | G13: m - ds | H13: =G10-J10 -> 227.5594
A14: cesjzpbs | B14: ='My trades'!G14-'My trades'!D14 -> 109 | C14: =('My trades'!H14-'My trades'!F14)*'My trades'!E14 -> 2.9151707 | G14: m + ds | H14: =G10+J10 -> 672.0306
A15: tgayvhvz | B15: ='My trades'!G145-'My trades'!D145 -> 123 | C15: =('My trades'!H145-'My trades'!F145)*'My trades'!E145 -> 0.63398607 | G15: osservazioni in range | H15: =118/200 -> 0.59
A16: nuleyiit | B16: ='My trades'!G108-'My trades'!D108 -> 126 | C16: =('My trades'!H108-'My trades'!F108)*'My trades'!E108 -> 2.0673886
A17: fjhbimle | B17: ='My trades'!G38-'My trades'!D38 -> 130 | C17: =('My trades'!H38-'My trades'!F38)*'My trades'!E38 -> -0.41919268
A18: uijhzhtp | B18: ='My trades'!G158-'My trades'!D158 -> 141 | C18: =('My trades'!H158-'My trades'!F158)*'My trades'!E158 -> -0.33733947
A19: waxzujox | B19: ='My trades'!G169-'My trades'!D169 -> 143 | C19: =('My trades'!H169-'My trades'!F169)*'My trades'!E169 -> 0.03317406
A20: wfglkcmq | B20: ='My trades'!G170-'My trades'!D170 -> 143 | C20: =('My trades'!H170-'My trades'!F170)*'My trades'!E170 -> 0.44657129
A21: seszlhqz | B21: ='My trades'!G140-'My trades'!D140 -> 146 | C21: =('My trades'!H140-'My trades'!F140)*'My trades'!E140 -> 0.821921 | E21: L'istogramma rappresenta la distribuzione del perdiodo di possesso dei trades. La distribuzione non è una distribuzione normale, visivamente non si evidenzia un picco centrale e l'andamento è piuttosto appiattito. A supporto sono state calcolate le principali statistiche descrittive che evidenziano come media, mediana e moda non coincidano, sebbene media e mediana siano vicine (449 e 444), si nota un evidente distacco della moda (623) che di conseguenza non divide 50% delle osservazioni al di sotto di essa e 50% al si sopra . Inoltre, la deviazione standard è molto elevata (222,2) e questo evidenzia variabilità dei dati e di conseguenza c'è dispersione rispetto alla media. E' stato infine calcolato il range media - dev. standard (227,6) e media + dev standard (672), applicando un filtro, ordinando i valori nella colonna b e conteggiando i valori che ricadono nel range il risultato è di 118 che espresso in percentuale è pari al 59% dei casi, numero molto inferiore rispetto a quanto ci si aspetterebbe da una distribuzione normale (68% dei casi)
A22: vajwbmmv | B22: ='My trades'!G164-'My trades'!D164 -> 148 | C22: =('My trades'!H164-'My trades'!F164)*'My trades'!E164 -> -0.28002139
A23: qexyofhb | B23: ='My trades'!G127-'My trades'!D127 -> 152 | C23: =('My trades'!H127-'My trades'!F127)*'My trades'!E127 -> -0.54187349
A24: zsbkamjf | B24: ='My trades'!G199-'My trades'!D199 -> 159 | C24: =('My trades'!H199-'My trades'!F199)*'My trades'!E199 -> 1.4526226
A25: hfwtmipz | B25: ='My trades'!G56-'My trades'!D56 -> 162 | C25: =('My trades'!H56-'My trades'!F56)*'My trades'!E56 -> 2.8245213
A26: nzyednpn | B26: ='My trades'!G109-'My trades'!D109 -> 163 | C26: =('My trades'!H109-'My trades'!F109)*'My trades'!E109 -> 4.3623327
A27: seaeoiib | B27: ='My trades'!G138-'My trades'!D138 -> 169 | C27: =('My trades'!H138-'My trades'!F138)*'My trades'!E138 -> -1.352458
A28: xgimgqvp | B28: ='My trades'!G177-'My trades'!D177 -> 172 | C28: =('My trades'!H177-'My trades'!F177)*'My trades'!E177 -> -1.5256033
A29: pywztrno | B29: ='My trades'!G125-'My trades'!D125 -> 175 | C29: =('My trades'!H125-'My trades'!F125)*'My trades'!E125 -> -0.51703472
A30: iagrfath | B30: ='My trades'!G63-'My trades'!D63 -> 181 | C30: =('My trades'!H63-'My trades'!F63)*'My trades'!E63 -> 0.40069794
A31: ywfotaaf | B31: ='My trades'!G193-'My trades'!D193 -> 181 | C31: =('My trades'!H193-'My trades'!F193)*'My trades'!E193 -> -0.66490583
A32: pswtoazn | B32: ='My trades'!G120-'My trades'!D120 -> 184 | C32: =('My trades'!H120-'My trades'!F120)*'My trades'!E120 -> -0.62322749
A33: kmlcsefq | B33: ='My trades'!G80-'My trades'!D80 -> 199 | C33: =('My trades'!H80-'My trades'!F80)*'My trades'!E80 -> -0.20085806
A34: iztdnkqz | B34: ='My trades'!G69-'My trades'!D69 -> 204 | C34: =('My trades'!H69-'My trades'!F69)*'My trades'!E69 -> -2.5716033
A35: dspetbsq | B35: ='My trades'!G27-'My trades'!D27 -> 207 | C35: =('My trades'!H27-'My trades'!F27)*'My trades'!E27 -> -5.4295327
A36: kwbxqlin | B36: ='My trades'!G87-'My trades'!D87 -> 207 | C36: =('My trades'!H87-'My trades'!F87)*'My trades'!E87 -> 5.5166452
A37: kqbdcljv | B37: ='My trades'!G85-'My trades'!D85 -> 212 | C37: =('My trades'!H85-'My trades'!F85)*'My trades'!E85 -> 1.3297795
A38: vnkvbrpg | B38: ='My trades'!G167-'My trades'!D167 -> 213 | C38: =('My trades'!H167-'My trades'!F167)*'My trades'!E167 -> 3.0343474
A39: jhrvrggo | B39: ='My trades'!G72-'My trades'!D72 -> 222 | C39: =('My trades'!H72-'My trades'!F72)*'My trades'!E72 -> 0.078785101
A40: giuqiukz | B40: ='My trades'!G45-'My trades'!D45 -> 227 | C40: =('My trades'!H45-'My trades'!F45)*'My trades'!E45 -> -0.55470984
...

Sheet Number of Trades Exchanged
A1: Region | B1: Quantity
A2: India | B2: 7
A3: Iran | B3: 2
A4: India | B4: 6
A5: Switzerland | B5: 1
A6: India | B6: 9
A7: Europe | B7: 1
A8: South Korea | B8: 3
A9: South Africa | B9: 4
A10: Canada | B10: 10
A11: Europe | B11: 6
A12: Germany | B12: 5
A13: India | B13: 10
... A22: United Kingdom | B22: 1
A23: India | B23: 9 | D23: P(UK = 1) | E23: =GETPIVOTDATA("Quantity",$D$1,"Region","United Kingdom","Quantity",1)/GETPIVOTDATA("Quantity",$D$1) -> 0.005 | F23: =E23 -> 0.005
A24: Brazil | B24: 2 | D24: P(Asia e <=8) | E24: =(GETPIVOTDATA("Quantity",$D$1,"Region","China","Quantity",8)+GETPIVOTDATA("Quantity",$D$1,"Region","China","Quantity",6)+GETPIVOTDATA("Quantity",$D$1,"Region","China","Quantity",5)+GETPIVOTDATA("Quantity",$D$1,"Region","China","Quantity",4)+GETPIVOTDATA("Quantity",$D$1,"Region","China","Quantity",3)+GETPIVOTDATA("Quantity",$D$1,"Region","China","Quantity",2)+GETPIVOTDATA("Quantity",$D$1,"Region","China","Quantity",1)+GETPIVOTDATA("Quantity",$D$1,"Region","Hong Kong","Quantity",7)+GETPIVOTDATA("Quantity",$D$1,"Region","Hong Kong","Quantity",6)+GETPIVOTDATA("Quantity",$D$1,"Region","Hong Kong","Quantity",5)+GETPIVOTDATA("Quantity",$D$1,"Region","India","Quantity",8)+GETPIVOTDATA("Quantity",$D$1,"Region","India","Quantity",7)+GETPIVOTDATA("Quantity",$D$1,"Region","India","Quantity",6)+GETPIVOTDATA("Quantity",$D$1,"Region","India","Quantity",5)+GETPIVOTDATA("Quantity",$D$1,"Region","India","Quantity",4)+GETPIVOTDATA("Quantity",$D$1,"Region","India","Quantity",3)+GETPIVOTDATA("Quantity",$D$1,"Region","India","Quantity",2)+GETPIVOTDATA("Quantity",$D$1,"Region","India","Quantity",1)+GETPIVOTDATA("Quantity",$D$1,"Region","Iran","Quantity",8)+GETPIVOTDATA("Quantity",$D$1,"Region","Iran","Quantity",6)+GETPIVOTDATA("Quantity",$D$1,"Region","Iran","Quantity",5)+GETPIVOTDATA("Quantity",$D$1,"Region","Iran","Quantity",4)+GETPIVOTDATA("Quantity",$D$1,"Region","Iran","Quantity",3)+GETPIVOTDATA("Quantity",$D$1,"Region","Iran","Quantity",2)+GETPIVOTDATA("Quantity",$D$1,"Region","Japan","Quantity",8)+GETPIVOTDATA("Quantity",$D$1,"Region","Japan","Quantity",6)+GETPIVOTDATA("Quantity",$D$1,"Region","Japan","Quantity",3)+GETPIVOTDATA("Quantity",$D$1,"Region","Japan","Quantity",2)+GETPIVOTDATA("Quantity",$D$1,"Region","Japan","Quantity",1)+GETPIVOTDATA("Quantity",$D$1,"Region","Saudi Arabia","Quantity",7)+GETPIVOTDATA("Quantity",$D$1,"Region","Saudi Arabia","Quantity",6)+GETPIVOTDATA("Quantity",$D$1,"Region","Saudi Arabia","Quantity",5)+GETPIVOTDATA("Quantity",$D$1,"Region","Saudi Arabia","Quantity",2)+GETPIVOTDATA("Quantity",$D$1,"Region","Saudi Arabia","Quantity",1)+GETPIVOTDATA("Quantity",$D$1,"Region","South Korea","Quantity",8)+GETPIVOTDATA("Quantity",$D$1,"Region","South Korea","Quantity",7)+GETPIVOTDATA("Quantity",$D$1,"Region","South Korea","Quantity",6)+GETPIVOTDATA("Quantity",$D$1,"Region","South Korea","Quantity",3)+GETPIVOTDATA("Quantity",$D$1,"Region","South Korea","Quantity",1)+GETPIVOTDATA("Quantity",$D$1,"Region","Taiwan","Quantity",7)+GETPIVOTDATA("Quantity",$D$1,"Region","Taiwan","Quantity",5)+GETPIVOTDATA("Quantity",$D$1,"Region","Taiwan","Quantity",4)+GETPIVOTDATA("Quantity",$D$1,"Region","Taiwan","Quantity",3))/GETPIVOTDATA("Quantity",$D$1) -> 0.37 | F24: =E24 -> 0.37
A25: United States | B25: 3
A26: Canada | B26: 2
A27: Brazil | B27: 8
A28: South Korea | B28: 7
A29: India | B29: 1
A30: India | B30: 3
A31: Germany | B31: 1
A32: United Kingdom | B32: 7
A33: China | B33: 9
A34: Taiwan | B34: 9
A35: Germany | B35: 5
A36: Switzerland | B36: 8
... A201: Brazil | B201: 8
